<?xml version="1.0" ?>
<!-- =================================================================================== -->
<!-- |    This document was autogenerated by xacro from youbot.urdf.xacro              | -->
<!-- |    EDITING THIS FILE BY HAND IS NOT RECOMMENDED                                 | -->
<!-- =================================================================================== -->
<robot name="youbot_urdf" xmlns:controller="http://playerstage.sourceforge.net/gazebo/xmlschema/#controller" xmlns:interface="http://playerstage.sourceforge.net/gazebo/xmlschema/#interface" xmlns:sensor="http://playerstage.sourceforge.net/gazebo/xmlschema/#sensor" xmlns:xacro="http://ros.org/wiki/xacro">
  <!-- The following included files set up definitions of parts of the robot body -->
  <!-- misc common stuff? -->
  <!-- youbot base -->
  <!-- youbot plate -->
  <!-- youbot arm -->
  <!-- youbot gripper -->
  <!-- generic simulator_gazebo plugins for starting mechanism control, ros time, ros battery -->
  <gazebo>
    <plugin filename="libgazebo_ros_controller_manager.so" name="gazebo_ros_controller_manager">
      <alwaysOn>true</alwaysOn>
      <updateRate>1000.0</updateRate>
      <interface:audio name="gazebo_ros_controller_manager_dummy_iface"/>
    </plugin>
    <plugin filename="libgazebo_ros_power_monitor.so" name="gazebo_ros_power_monitor_controller">
      <alwaysOn>true</alwaysOn>
      <updateRate>1.0</updateRate>
      <timeout>5</timeout>
      <interface:audio name="power_monitor_dummy_interface"/>
      <powerStateTopic>power_state</powerStateTopic>
      <powerStateRate>10.0</powerStateRate>
      <fullChargeCapacity>87.78</fullChargeCapacity>
      <dischargeRate>-474</dischargeRate>
      <chargeRate>525</chargeRate>
      <dischargeVoltage>15.52</dischargeVoltage>
      <chargeVoltage>16.41</chargeVoltage>
    </plugin>
  </gazebo>
  <!-- materials for visualization -->
  <material name="Orange">
    <color rgba="1.0 0.4 0.0 1.0"/>
  </material>
  <material name="Grey">
    <color rgba="0.7 0.7 0.7 1.0"/>
  </material>
  <material name="DarkGrey">
    <color rgba="0.3 0.3 0.3 1.0"/>
  </material>
  <material name="White">
    <color rgba="1.0 1.0 1.0 1.0"/>
  </material>
  <material name="Black">
    <color rgba="0.0 0.0 0.0 1.0"/>
  </material>
  <material name="Red">
    <color rgba="1.0 0.0 0.0 1.0"/>
  </material>
  <material name="Green">
    <color rgba="0.0 1.0 0.0 1.0"/>
  </material>
  <!-- Now we can start using the macros included above to define the actual youbot -->
  <!-- The first use of a macro.  This one was defined in base.urdf.xacro above.
       A macro like this will expand to a set of link and joint definitions, and to additional
       Gazebo-related extensions (sensor plugins, etc).  The macro takes an argument, name, 
       that equals "base", and uses it to generate names for its component links and joints 
       (e.g., base_link).  The included origin block is also an argument to the macro.  By convention, 
       the origin block defines where the component is w.r.t its parent (in this case the parent 
       is the world frame). For more, see http://www.ros.org/wiki/xacro -->
  <!-- foot for arm-->
  <link name="base_footprint">
    <inertial>
      <mass value="0.1"/>
      <origin rpy="0 0 0" xyz="0 0 -0.05"/>
      <inertia ixx="1.0" ixy="0.0" ixz="0.0" iyy="1.0" iyz="0.0" izz="1.0"/>
    </inertial>
    <visual>
      <origin rpy="0 0 0" xyz="0 0 0"/>
      <geometry>
        <box size="0.001 0.001 0.001"/>
      </geometry>
      <material name="Red"/>
    </visual>
    <collision>
      <origin rpy="0 0 0" xyz="0 0 -0.05"/>
      <geometry>
        <box size="0.001 0.001 0.001"/>
      </geometry>
    </collision>
  </link>
  <joint name="base_footprint_joint" type="fixed">
    <origin rpy="0 0 0" xyz="0 0 0"/>
    <child link="base_link"/>
    <parent link="base_footprint"/>
  </joint>
  <link name="base_link">
    <inertial>
      <mass value="22.0"/>
      <origin xyz="0 0 0"/>
      <inertia ixx="5.652232699207" ixy="-0.009719934438" ixz="1.293988226423" iyy="5.669473158652" iyz="-0.007379583694" izz="3.683196351726"/>
    </inertial>
    <visual>
      <origin rpy="0 0 0" xyz="0 0 0"/>
      <geometry>
        <mesh filename="package://youbot_description/meshes/youbot_base/base.dae"/>
      </geometry>
      <material name="Black"/>
    </visual>
    <collision>
      <origin rpy="0 0 0" xyz="0 0 0"/>
      <geometry>
        <!--<box size="${base_size_x} ${base_size_y} ${base_size_z}" />-->
        <mesh filename="package://youbot_description/meshes/youbot_base/base_convex.dae"/>
      </geometry>
    </collision>
  </link>
  <joint name="ultrasonic_frame_0_ultrasonicleftfront_laser_joint" type="fixed">
    <axis xyz="0 1 0"/>
    <origin rpy="0 0 1.57079632679" xyz="0.08 0.18 -0.067"/>
    <parent link="base_link"/>
    <child link="ultrasonic_frame_0_link"/>
  </joint>
  <link name="ultrasonic_frame_0_link" type="laser">
    <inertial>
      <mass value="0.16"/>
      <origin rpy="0 0 0" xyz="0 0 0"/>
      <inertia ixx="0.1" ixy="0" ixz="0" iyy="0.1" iyz="0" izz="0.1"/>
    </inertial>
    <visual>
      <origin rpy="0 0 0" xyz="0 0 0"/>
      <geometry>
        <mesh filename="package://youbot_description/meshes/sensors/ultrasonic.stl"/>
      </geometry>
      <material name="Black"/>
    </visual>
    <collision>
      <origin rpy="0 0 0" xyz="0 0 0"/>
      <geometry>
        <mesh filename="package://youbot_description/meshes/sensors/ultrasonic_collider.stl"/>
      </geometry>
    </collision>
  </link>
  <xacro:ultrasonicleftfront_laser_gazebo max_angle="0.392699081699" min_angle="-0.392699081699" name="ultrasonic_frame_0" ros_topic="ultrasonic_scan_0" update_rate="10"/>
  <joint name="ultrasonic_frame_1_ultrasonicleftback_laser_joint" type="fixed">
    <axis xyz="0 1 0"/>
    <origin rpy="0 0 1.57079632679" xyz="-0.08 0.18 -0.067"/>
    <parent link="base_link"/>
    <child link="ultrasonic_frame_1_link"/>
  </joint>
  <link name="ultrasonic_frame_1_link" type="laser">
    <inertial>
      <mass value="0.16"/>
      <origin rpy="0 0 0" xyz="0 0 0"/>
      <inertia ixx="0.1" ixy="0" ixz="0" iyy="0.1" iyz="0" izz="0.1"/>
    </inertial>
    <visual>
      <origin rpy="0 0 0" xyz="0 0 0"/>
      <geometry>
        <mesh filename="package://youbot_description/meshes/sensors/ultrasonic.stl"/>
      </geometry>
      <material name="Black"/>
    </visual>
    <collision>
      <origin rpy="0 0 0" xyz="0 0 0"/>
      <geometry>
        <mesh filename="package://youbot_description/meshes/sensors/ultrasonic_collider.stl"/>
      </geometry>
    </collision>
  </link>
  <gazebo reference="ultrasonic_frame_1_link">
    <sensor name="ultrasonic_frame_1" type="ray">
      <pose>0 0 0 0 0 0</pose>
      <ray>
        <scan>
          <horizontal>
            <samples>640</samples>
            <resolution>1</resolution>
            <min_angle>-22.5</min_angle>
            <max_angle>1-22.5</max_angle>
          </horizontal>
        </scan>
        <range>
          <min>0.050000</min>
          <max>5.600000</max>
          <resolution>0.360000</resolution>
        </range>
      </ray>
      <always_on>0</always_on>
      <update_rate>10</update_rate>
      <visualize>0</visualize>
      <plugin filename="libgazebo_ros_laser.so" name="gazebo_ros_laser">
        <gaussianNoise>0.02</gaussianNoise>
        <alwaysOn>true</alwaysOn>
        <hokuyoMinIntensity>101</hokuyoMinIntensity>
        <updateRate>10</updateRate>
        <topicName>ultrasonic_scan_1</topicName>
        <frameName>/ultrasonic_frame_1_link</frameName>
        <interface:laser name="gazebo_ros_ultrasonic_frame_1_iface"/>
      </plugin>
    </sensor>
  </gazebo>
  <joint name="ultrasonic_frame_2_ultrasonicrightfront_laser_joint" type="fixed">
    <axis xyz="0 1 0"/>
    <origin rpy="0 0 -1.57079632679" xyz="0.08 -0.18 -0.067"/>
    <parent link="base_link"/>
    <child link="ultrasonic_frame_2_link"/>
  </joint>
  <link name="ultrasonic_frame_2_link" type="laser">
    <inertial>
      <mass value="0.16"/>
      <origin rpy="0 0 0" xyz="0 0 0"/>
      <inertia ixx="0.1" ixy="0" ixz="0" iyy="0.1" iyz="0" izz="0.1"/>
    </inertial>
    <visual>
      <origin rpy="0 0 0" xyz="0 0 0"/>
      <geometry>
        <mesh filename="package://youbot_description/meshes/sensors/ultrasonic.stl"/>
      </geometry>
      <material name="Black"/>
    </visual>
    <collision>
      <origin rpy="0 0 0" xyz="0 0 0"/>
      <geometry>
        <mesh filename="package://youbot_description/meshes/sensors/ultrasonic_collider.stl"/>
      </geometry>
    </collision>
  </link>
  <xacro:ultrasonicrightfront_laser_gazebo max_angle="0.392699081699" min_angle="-0.392699081699" name="ultrasonic_frame_2" ros_topic="ultrasonic_scan_2" update_rate="10"/>
  <joint name="ultrasonic_frame_3_ultrasonicrightback_laser_joint" type="fixed">
    <axis xyz="0 1 0"/>
    <origin rpy="0 0 -1.57079632679" xyz="-0.08 -0.18 -0.067"/>
    <parent link="base_link"/>
    <child link="ultrasonic_frame_3_link"/>
  </joint>
  <link name="ultrasonic_frame_3_link" type="laser">
    <inertial>
      <mass value="0.16"/>
      <origin rpy="0 0 0" xyz="0 0 0"/>
      <inertia ixx="0.1" ixy="0" ixz="0" iyy="0.1" iyz="0" izz="0.1"/>
    </inertial>
    <visual>
      <origin rpy="0 0 0" xyz="0 0 0"/>
      <geometry>
        <mesh filename="package://youbot_description/meshes/sensors/ultrasonic.stl"/>
      </geometry>
      <material name="Black"/>
    </visual>
    <collision>
      <origin rpy="0 0 0" xyz="0 0 0"/>
      <geometry>
        <mesh filename="package://youbot_description/meshes/sensors/ultrasonic_collider.stl"/>
      </geometry>
    </collision>
  </link>
  <xacro:ultrasonicrightback_laser_gazebo max_angle="0.392699081699" min_angle="-0.392699081699" name="ultrasonic_frame_3" ros_topic="ultrasonic_scan_3" update_rate="10"/>
  <joint name="base_laser_front_hokuyo_urg04_laser_joint" type="fixed">
    <axis xyz="0 1 0"/>
    <origin rpy="0 0 0" xyz="0.3 0 -0.03"/>
    <parent link="base_link"/>
    <child link="base_laser_front_link"/>
  </joint>
  <link name="base_laser_front_link" type="laser">
    <inertial>
      <mass value="0.16"/>
      <origin rpy="0 0 0" xyz="0 0 0"/>
      <inertia ixx="0.1" ixy="0" ixz="0" iyy="0.1" iyz="0" izz="0.1"/>
    </inertial>
    <visual>
      <origin rpy="0 0 0" xyz="0 0 0"/>
      <geometry>
        <mesh filename="package://youbot_description/meshes/sensors/hokuyo.dae"/>
      </geometry>
      <material name="DarkGrey"/>
    </visual>
    <collision>
      <origin rpy="0 0 0" xyz="0 0 0"/>
      <geometry>
        <mesh filename="package://youbot_description/meshes/sensors/hokuyo_convex.dae"/>
      </geometry>
    </collision>
  </link>
  <gazebo reference="base_laser_front_link">
    <sensor name="base_laser_front" type="ray">
      <pose>0 0 0 0 0 0</pose>
      <ray>
        <scan>
          <horizontal>
            <samples>640</samples>
            <resolution>1</resolution>
            <min_angle>-1.570000</min_angle>
            <max_angle>1.570000</max_angle>
          </horizontal>
        </scan>
        <range>
          <min>0.050000</min>
          <max>5.600000</max>
          <resolution>0.360000</resolution>
        </range>
      </ray>
      <always_on>0</always_on>
      <update_rate>10</update_rate>
      <visualize>0</visualize>
      <plugin filename="libgazebo_ros_laser.so" name="gazebo_ros_laser">
        <gaussianNoise>0.02</gaussianNoise>
        <alwaysOn>true</alwaysOn>
        <hokuyoMinIntensity>101</hokuyoMinIntensity>
        <updateRate>10</updateRate>
        <topicName>scan_front</topicName>
        <frameName>/base_laser_front_link</frameName>
        <interface:laser name="gazebo_ros_base_laser_front_iface"/>
      </plugin>
    </sensor>
  </gazebo>
  <joint name="caster_joint_fl" type="continuous">
    <origin rpy="0 0 0" xyz="0.228 0.158 -0.034"/>
    <axis xyz="0 0 1"/>
    <limit effort="30" velocity="10"/>
    <dynamics damping="1.0" friction="1.0"/>
    <safety_controller k_velocity="10.0"/>
    <parent link="base_link"/>
    <child link="caster_link_fl"/>
  </joint>
  <link name="caster_link_fl">
    <inertial>
      <mass value="0.1"/>
      <origin xyz="0 0 0"/>
      <inertia ixx="0.012411765597" ixy="-0.000711733678" ixz="0.00050272983" iyy="0.015218160428" iyz="-0.000004273467" izz="0.011763977943"/>
    </inertial>
  </link>
  <joint name="wheel_joint_fl" type="continuous">
    <axis xyz="0 1 0"/>
    <limit effort="30" velocity="10"/>
    <origin rpy="0 0 0" xyz="0.0 0.0 0.0"/>
    <parent link="caster_link_fl"/>
    <dynamics damping="1.0" friction="1.0"/>
    <safety_controller k_velocity="10.0"/>
    <child link="wheel_link_fl"/>
  </joint>
  <link name="wheel_link_fl">
    <inertial>
      <mass value="0.4"/>
      <origin xyz="0 0 0"/>
      <inertia ixx="0.012411765597" ixy="-0.000711733678" ixz="0.00050272983" iyy="0.015218160428" iyz="-0.000004273467" izz="0.011763977943"/>
    </inertial>
    <visual>
      <origin rpy="0 0 0" xyz="0 0 0"/>
      <!--<mesh filename="package://youbot_description/meshes/youbot_base/youbot_wheel.stl" />-->
      <geometry>
        <sphere radius="0.05"/>
      </geometry>
      <material name="Orange"/>
    </visual>
    <collision>
      <origin rpy="1.57079632679 0 0" xyz="0 0 0"/>
      <geometry>
        <cylinder length="0.05" radius="0.05"/>
      </geometry>
    </collision>
  </link>
  <joint name="caster_joint_fr" type="continuous">
    <origin rpy="0 0 0" xyz="0.228 -0.158 -0.034"/>
    <axis xyz="0 0 1"/>
    <limit effort="30" velocity="10"/>
    <dynamics damping="1.0" friction="1.0"/>
    <safety_controller k_velocity="10.0"/>
    <parent link="base_link"/>
    <child link="caster_link_fr"/>
  </joint>
  <link name="caster_link_fr">
    <inertial>
      <mass value="0.1"/>
      <origin xyz="0 0 0"/>
      <inertia ixx="0.012411765597" ixy="-0.000711733678" ixz="0.00050272983" iyy="0.015218160428" iyz="-0.000004273467" izz="0.011763977943"/>
    </inertial>
  </link>
  <joint name="wheel_joint_fr" type="continuous">
    <axis xyz="0 1 0"/>
    <limit effort="30" velocity="10"/>
    <dynamics damping="1.0" friction="1.0"/>
    <safety_controller k_velocity="10.0"/>
    <origin rpy="0 0 0" xyz="0.0 0.0 0.0"/>
    <parent link="caster_link_fr"/>
    <child link="wheel_link_fr"/>
  </joint>
  <link name="wheel_link_fr">
    <inertial>
      <mass value="0.4"/>
      <origin xyz="0 0 0"/>
      <inertia ixx="0.012411765597" ixy="-0.000711733678" ixz="0.00050272983" iyy="0.015218160428" iyz="-0.000004273467" izz="0.011763977943"/>
    </inertial>
    <visual>
      <origin rpy="0 0 0" xyz="0 0 0"/>
      <geometry>
        <!--<mesh filename="package://youbot_description/meshes/youbot_base/youbot_wheel.stl" />-->
        <sphere radius="0.05"/>
      </geometry>
      <material name="Orange"/>
    </visual>
    <collision>
      <origin rpy="1.57079632679 0 0" xyz="0 0 0"/>
      <geometry>
        <cylinder length="0.05" radius="0.05"/>
      </geometry>
    </collision>
  </link>
  <joint name="caster_joint_bl" type="continuous">
    <origin rpy="0 0 0" xyz="-0.228 0.158 -0.034"/>
    <axis xyz="0 0 1"/>
    <limit effort="30" velocity="10"/>
    <dynamics damping="1.0" friction="1.0"/>
    <safety_controller k_velocity="10.0"/>
    <parent link="base_link"/>
    <child link="caster_link_bl"/>
  </joint>
  <link name="caster_link_bl">
    <inertial>
      <mass value="0.1"/>
      <origin xyz="0 0 0"/>
      <inertia ixx="0.012411765597" ixy="-0.000711733678" ixz="0.00050272983" iyy="0.015218160428" iyz="-0.000004273467" izz="0.011763977943"/>
    </inertial>
  </link>
  <joint name="wheel_joint_bl" type="continuous">
    <axis xyz="0 1 0"/>
    <limit effort="10" velocity="10"/>
    <limit effort="30" velocity="10"/>
    <dynamics damping="1.0" friction="1.0"/>
    <safety_controller k_velocity="10.0"/>
    <origin rpy="0 0 0" xyz="0.0 0.0 0.0"/>
    <parent link="caster_link_bl"/>
    <child link="wheel_link_bl"/>
  </joint>
  <link name="wheel_link_bl">
    <inertial>
      <mass value="0.4"/>
      <origin xyz="0 0 0"/>
      <inertia ixx="0.012411765597" ixy="-0.000711733678" ixz="0.00050272983" iyy="0.015218160428" iyz="-0.000004273467" izz="0.011763977943"/>
    </inertial>
    <visual>
      <origin rpy="0 0 0" xyz="0 0 0"/>
      <geometry>
        <!--<mesh filename="package://youbot_description/meshes/youbot_base/youbot_wheel.stl" />-->
        <sphere radius="0.05"/>
      </geometry>
      <material name="Orange"/>
    </visual>
    <collision>
      <origin rpy="1.57079632679 0 0" xyz="0 0 0"/>
      <geometry>
        <cylinder length="0.05" radius="0.05"/>
      </geometry>
    </collision>
  </link>
  <joint name="caster_joint_br" type="continuous">
    <origin rpy="0 0 0" xyz="-0.228 -0.158 -0.034"/>
    <axis xyz="0 0 1"/>
    <limit effort="30" velocity="10"/>
    <dynamics damping="1.0" friction="1.0"/>
    <safety_controller k_velocity="10.0"/>
    <parent link="base_link"/>
    <child link="caster_link_br"/>
  </joint>
  <link name="caster_link_br">
    <inertial>
      <mass value="0.1"/>
      <origin xyz="0 0 0"/>
      <inertia ixx="0.012411765597" ixy="-0.000711733678" ixz="0.00050272983" iyy="0.015218160428" iyz="-0.000004273467" izz="0.011763977943"/>
    </inertial>
  </link>
  <joint name="wheel_joint_br" type="continuous">
    <axis xyz="0 1 0"/>
    <limit effort="30" velocity="10"/>
    <dynamics damping="1.0" friction="1.0"/>
    <safety_controller k_velocity="10.0"/>
    <origin rpy="0 0 0" xyz="0.0 0.0 0.0"/>
    <parent link="caster_link_br"/>
    <child link="wheel_link_br"/>
  </joint>
  <link name="wheel_link_br">
    <inertial>
      <mass value="0.4"/>
      <origin xyz="0 0 0"/>
      <inertia ixx="0.012411765597" ixy="-0.000711733678" ixz="0.00050272983" iyy="0.015218160428" iyz="-0.000004273467" izz="0.011763977943"/>
    </inertial>
    <visual>
      <origin rpy="0 0 0" xyz="0 0 0"/>
      <geometry>
        <!--<mesh filename="package://youbot_description/meshes/youbot_base/youbot_wheel.stl" />-->
        <sphere radius="0.05"/>
      </geometry>
      <material name="Orange"/>
    </visual>
    <collision>
      <origin rpy="1.57079632679 0 0" xyz="0 0 0"/>
      <geometry>
        <cylinder length="0.05" radius="0.05"/>
      </geometry>
    </collision>
  </link>
  <gazebo reference="youbot_base">
    <material value="youbot/DarkGrey"/>
  </gazebo>
  <gazebo reference="wheel_link_fl">
    <material value="youbot/Orange"/>
  </gazebo>
  <gazebo reference="caster_link_fl">
    <material value="youbot/Orange"/>
  </gazebo>
  <gazebo reference="wheel_link_fr">
    <material value="youbot/Orange"/>
  </gazebo>
  <gazebo reference="caster_link_fr">
    <material value="youbot/Orange"/>
  </gazebo>
  <gazebo reference="wheel_link_bl">
    <material value="youbot/Orange"/>
  </gazebo>
  <gazebo reference="caster_link_bl">
    <material value="youbot/Orange"/>
  </gazebo>
  <gazebo reference="wheel_link_br">
    <material value="youbot/Orange"/>
  </gazebo>
  <gazebo reference="caster_link_br">
    <material value="youbot/Orange"/>
  </gazebo>
  <gazebo>
    <plugin filename="libgazebo_ros_p3d.so" name="gazebo_ros_p3d">
      <alwaysOn>true</alwaysOn>
      <updateRate>100.0</updateRate>
      <bodyName>base_link</bodyName>
      <topicName>base_pose_ground_truth</topicName>
      <gaussianNoise>0.01</gaussianNoise>
      <frameName>map</frameName>
      <xyzOffsets>25.7 25.7 0</xyzOffsets>
      <!-- initialize odometry for fake localization-->
      <rpyOffsets>0 0 0</rpyOffsets>
      <interface:position name="p3d_base_position"/>
    </plugin>
    <canonicalBody>base_footprint</canonicalBody>
  </gazebo>
  <transmission name="wheel_trans_fl" type="pr2_mechanism_model/SimpleTransmission">
    <actuator name="wheel_motor_fl"/>
    <joint name="wheel_joint_fl"/>
    <mechanicalReduction>79.2380952381</mechanicalReduction>
  </transmission>
  <transmission name="caster_trans_fl" type="pr2_mechanism_model/SimpleTransmission">
    <actuator name="caster_motor_fl"/>
    <joint name="caster_joint_fl"/>
    <mechanicalReduction>79.2380952381</mechanicalReduction>
  </transmission>
  <transmission name="wheel_trans_fr" type="pr2_mechanism_model/SimpleTransmission">
    <actuator name="wheel_motor_fr"/>
    <joint name="wheel_joint_fr"/>
    <mechanicalReduction>79.2380952381</mechanicalReduction>
  </transmission>
  <transmission name="caster_trans_fr" type="pr2_mechanism_model/SimpleTransmission">
    <actuator name="caster_motor_fr"/>
    <joint name="caster_joint_fr"/>
    <mechanicalReduction>79.2380952381</mechanicalReduction>
  </transmission>
  <transmission name="wheel_trans_bl" type="pr2_mechanism_model/SimpleTransmission">
    <actuator name="wheel_motor_bl"/>
    <joint name="wheel_joint_bl"/>
    <mechanicalReduction>79.2380952381</mechanicalReduction>
  </transmission>
  <transmission name="caster_trans_bl" type="pr2_mechanism_model/SimpleTransmission">
    <actuator name="caster_motor_bl"/>
    <joint name="caster_joint_bl"/>
    <mechanicalReduction>79.2380952381</mechanicalReduction>
  </transmission>
  <transmission name="wheel_trans_br" type="pr2_mechanism_model/SimpleTransmission">
    <actuator name="wheel_motor_br"/>
    <joint name="wheel_joint_br"/>
    <mechanicalReduction>79.2380952381</mechanicalReduction>
  </transmission>
  <transmission name="caster_trans_br" type="pr2_mechanism_model/SimpleTransmission">
    <actuator name="caster_motor_br"/>
    <joint name="caster_joint_br"/>
    <mechanicalReduction>79.2380952381</mechanicalReduction>
  </transmission>
  <joint name="plate_joint" type="fixed">
    <origin rpy="0 0 0" xyz="-0.159 0 0.046"/>
    <parent link="base_link"/>
    <child link="plate_link"/>
  </joint>
  <link name="plate_link">
    <inertial>
      <origin rpy="0 0 0" xyz="0 0 0"/>
      <mass value="1"/>
      <inertia ixx="0.01" ixy="0" ixz="0" iyy="0.01" iyz="0" izz="0.01"/>
    </inertial>
    <visual>
      <origin rpy="0 0 0" xyz="0 0 0"/>
      <geometry>
        <mesh filename="package://youbot_description/meshes/youbot_plate/plate.dae"/>
      </geometry>
      <material name="DarkGrey"/>
    </visual>
    <collision>
      <origin rpy="0 0 0" xyz="0 0 0"/>
      <geometry>
        <mesh filename="package://youbot_description/meshes/youbot_plate/plate_convex.dae"/>
      </geometry>
    </collision>
  </link>
  <joint name="arm_joint_0" type="fixed">
    <origin rpy="0 0 0" xyz="0.143 0 0.046"/>
    <parent link="base_link"/>
    <child link="arm_link_0"/>
  </joint>
  <link name="arm_link_0">
    <inertial>
      <!--<origin xyz="0.023 0 0.006" rpy="0 0 0"/>-->
      <origin rpy="0 0 0" xyz="0 0 0"/>
      <mass value="0.845"/>
      <inertia ixx="0.01" ixy="0" ixz="0" iyy="0.01" iyz="0" izz="0.01"/>
    </inertial>
    <visual>
      <origin rpy="0 0 0" xyz="0 0 0"/>
      <geometry>
        <mesh filename="package://youbot_description/meshes/youbot_arm/arm0.dae"/>
      </geometry>
      <material name="DarkGrey"/>
    </visual>
    <collision>
      <!--<origin xyz="0.023 0 0.006" rpy="0 0 0"/>-->
      <origin rpy="0 0 0" xyz="0 0 0"/>
      <geometry>
        <mesh filename="package://youbot_description/meshes/youbot_arm/arm0_convex.dae"/>
        <!--<cylinder length="0.078" radius="0.093"/>-->
      </geometry>
    </collision>
  </link>
  <joint name="arm_joint_1" type="revolute">
    <origin rpy="0 0 2.96705972839" xyz="0.024 0 0.096"/>
    <parent link="arm_link_0"/>
    <child link="arm_link_1"/>
    <axis xyz="0 0 -1"/>
    <!--<calibration rising="${arm_1_ref}" falling="${arm_1_ref}"/>-->
    <dynamics damping="1" friction="1"/>
    <!-- damping - N*s/m, N*s*m/rad -->
    <!-- friction - N, N*m -->
    <limit effort="9.5" lower="0" upper="5.89921287174" velocity="1.57079632679"/>
    <!--effort - N, N*m-->
    <!--velocity - m/s, rad/s-->
    <safety_controller k_position="20" k_velocity="1.51197195937" soft_lower_limit="0.001" soft_upper_limit="5.89821287174"/>
    <!--k_position N/m, N/rad-->
    <!--k_velocity N*s/m, N*s*m/rad-->
    <!--for details: http://www.ros.org/wiki/pr2_controller_manager/safety_limits-->
  </joint>
  <link name="arm_link_1">
    <inertial>
      <mass value="2.412"/>
      <origin rpy="0 0 0" xyz="0.01489 0.00213 0.00213"/>
      <inertia ixx="0.003863" ixy="-0.000979" ixz="0.000000" iyy="0.006196" iyz="0.000000" izz="0.006369"/>
    </inertial>
    <visual>
      <origin rpy="0 0 0" xyz="0 0 0"/>
      <geometry>
        <mesh filename="package://youbot_description/meshes/youbot_arm/arm1.dae"/>
      </geometry>
      <!--<material name="Orange" />-->
    </visual>
    <collision>
      <!--<origin xyz="0 0 -0.003" rpy="0 0 0" />-->
      <origin rpy="0 0 0" xyz="0 0 0"/>
      <geometry>
        <mesh filename="package://youbot_description/meshes/youbot_arm/arm1_convex.dae"/>
        <!--<cylinder length="0.102" radius="0.080"/>-->
      </geometry>
    </collision>
  </link>
  <joint name="arm_joint_2" type="revolute">
    <origin rpy="0 -1.1344640138 0" xyz="0.033 0 0.019"/>
    <parent link="arm_link_1"/>
    <child link="arm_link_2"/>
    <axis xyz="0 1 0"/>
    <!--<calibration rising="${arm_2_ref}" falling="${arm_2_ref}"/>-->
    <dynamics damping="1" friction="1"/>
    <limit effort="9.5" lower="0" upper="2.70526034059" velocity="1.57079632679"/>
    <safety_controller k_position="20" k_velocity="6.04788783749" soft_lower_limit="0.001" soft_upper_limit="2.70426034059"/>
  </joint>
  <link name="arm_link_2">
    <inertial>
      <mass value="1.155"/>
      <origin rpy="0 0 0" xyz="0.0017 -0.00297 0.10453"/>
      <inertia ixx="0.004447" ixy="0.000000" ixz="0.000000" iyy="0.004439" iyz="0.000000" izz="0.000823"/>
    </inertial>
    <visual>
      <origin rpy="0 0 0" xyz="0 -0.032 0.078"/>
      <geometry>
        <mesh filename="package://youbot_description/meshes/youbot_arm/arm2.dae"/>
      </geometry>
      <material name="Orange"/>
    </visual>
    <collision>
      <!--<origin xyz="0.001 -0.041 0.074" rpy="0 0 0" />-->
      <origin rpy="0 0 0" xyz="0 -0.032 0.078"/>
      <geometry>
        <mesh filename="package://youbot_description/meshes/youbot_arm/arm2_convex.dae"/>
        <!--<box size="0.074 0.082 0.222"/>-->
      </geometry>
    </collision>
  </link>
  <joint name="arm_joint_3" type="revolute">
    <origin rpy="0 2.54818070791 0" xyz="0.000 0.000 0.155"/>
    <parent link="arm_link_2"/>
    <child link="arm_link_3"/>
    <axis xyz="0 1 0"/>
    <dynamics damping="1" friction="1"/>
    <limit effort="6.0" lower="-5.18362787842" upper="0" velocity="1.57079632679"/>
    <safety_controller k_position="20" k_velocity="50" soft_lower_limit="-5.18262787842" soft_upper_limit="-0.001"/>
  </joint>
  <link name="arm_link_3">
    <inertial>
      <mass value="0.934"/>
      <origin rpy="0 0 0" xyz="0.0001 0.02107 0.0967"/>
      <inertia ixx="0.002571" ixy="0.000000" ixz="0.000000" iyy="0.002459" iyz="0.000000" izz="0.000535"/>
    </inertial>
    <visual>
      <origin rpy="0 0 0" xyz="0.000 0.028 0.079"/>
      <geometry>
        <mesh filename="package://youbot_description/meshes/youbot_arm/arm3.dae"/>
      </geometry>
      <material name="Orange"/>
    </visual>
    <collision>
      <!--<origin xyz="0.000 0.025 0.067" rpy="0 0 0" />-->
      <origin rpy="0 0 0" xyz="0.000 0.028 0.079"/>
      <geometry>
        <mesh filename="package://youbot_description/meshes/youbot_arm/arm3_convex.dae"/>
        <!--<box size="0.064 0.054 0.192"/>-->
      </geometry>
    </collision>
  </link>
  <joint name="arm_joint_4" type="revolute">
    <origin rpy="0 -1.78896248329 0" xyz="0.000 0.000 0.135"/>
    <parent link="arm_link_3"/>
    <child link="arm_link_4"/>
    <axis xyz="0 1 0"/>
    <!--<calibration rising="${arm_4_ref}" falling="${arm_4_ref}"/>-->
    <dynamics damping="1" friction="1"/>
    <limit effort="2.0" lower="0" upper="3.57792496659" velocity="1.57079632679"/>
    <safety_controller k_position="20" k_velocity="100" soft_lower_limit="0" soft_upper_limit="3.57692496659"/>
  </joint>
  <link name="arm_link_4">
    <inertial>
      <mass value="0.877"/>
      <origin rpy="0 0 0" xyz="0.00011 -0.02319 0.05103"/>
      <inertia ixx="0.001173" ixy="-0.000231" ixz="0.000000" iyy="0.001091" iyz="0.000000" izz="0.000869"/>
    </inertial>
    <visual>
      <origin rpy="0 0 0" xyz="0 -0.010 0.029"/>
      <geometry>
        <mesh filename="package://youbot_description/meshes/youbot_arm/arm4.dae"/>
      </geometry>
      <material name="Orange"/>
    </visual>
    <collision>
      <!--<origin xyz="0 0 0.026" rpy="0 0 0" />-->
      <origin rpy="0 0 0" xyz="0 -0.010 0.029"/>
      <geometry>
        <mesh filename="package://youbot_description/meshes/youbot_arm/arm4_convex.dae"/>
        <!--<box size="0.058 0.100 0.118"/>-->
      </geometry>
    </collision>
  </link>
  <joint name="arm_joint_5" type="revolute">
    <origin rpy="0 0 2.92342649709" xyz="-0.002 0 0.130"/>
    <parent link="arm_link_4"/>
    <child link="arm_link_5"/>
    <axis xyz="0 0 -1"/>
    <!--<calibration rising="${arm_5_ref}" falling="${arm_5_ref}"/>-->
    <dynamics damping="1" friction="1"/>
    <limit effort="1" lower="0" upper="5.84685299418" velocity="1.57079632679"/>
    <safety_controller k_position="20" k_velocity="100" soft_lower_limit="0" soft_upper_limit="5.84585299418"/>
  </joint>
  <link name="arm_link_5">
    <inertial>
      <mass value="0.251"/>
      <origin rpy="0 0 0" xyz="0.00115 0.0 -0.01683"/>
      <inertia ixx="0.000280" ixy="0.000000" ixz="0.000000" iyy="0.000119" iyz="0.000000" izz="0.000339"/>
    </inertial>
    <visual>
      <origin rpy="0 0 0" xyz="0.003 0 -0.034"/>
      <geometry>
        <mesh filename="package://youbot_description/meshes/youbot_arm/arm5.dae"/>
      </geometry>
      <material name="DarkGrey"/>
    </visual>
    <collision>
      <origin rpy="0 0 0" xyz="0.003 0 -0.034"/>
      <geometry>
        <mesh filename="package://youbot_description/meshes/youbot_arm/arm5_convex.dae"/>
        <!--<box size="0.054 0.096 0.030"/>-->
      </geometry>
    </collision>
  </link>
  <gazebo reference="arm_link_0">
    <!-- <material value="youbot/DarkGrey" /> -->
    <turnGravityOff>false</turnGravityOff>
  </gazebo>
  <gazebo reference="arm_link_1">
    <!--<material value="youbot/Orange" />-->
    <turnGravityOff>false</turnGravityOff>
  </gazebo>
  <gazebo reference="arm_link_2">
    <!--<material value="youbot/Orange" />-->
    <turnGravityOff>false</turnGravityOff>
  </gazebo>
  <gazebo reference="arm_link_3">
    <!--<material value="youbot/Orange" />-->
    <turnGravityOff>false</turnGravityOff>
  </gazebo>
  <gazebo reference="arm_link_4">
    <!--<material value="youbot/Orange" />-->
    <turnGravityOff>false</turnGravityOff>
  </gazebo>
  <gazebo reference="arm_link_5">
    <!--<material value="youbot/DarkGrey" />-->
    <turnGravityOff>false</turnGravityOff>
  </gazebo>
  <transmission name="arm_trans_1" type="pr2_mechanism_model/SimpleTransmission">
    <actuator name="arm_motor_1"/>
    <joint name="arm_joint_1"/>
    <mechanicalReduction>1</mechanicalReduction>
  </transmission>
  <transmission name="arm_trans_2" type="pr2_mechanism_model/SimpleTransmission">
    <actuator name="arm_motor_2"/>
    <joint name="arm_joint_2"/>
    <mechanicalReduction>1</mechanicalReduction>
  </transmission>
  <transmission name="arm_trans_3" type="pr2_mechanism_model/SimpleTransmission">
    <actuator name="arm_motor_3"/>
    <joint name="arm_joint_3"/>
    <mechanicalReduction>1</mechanicalReduction>
  </transmission>
  <transmission name="arm_trans_4" type="pr2_mechanism_model/SimpleTransmission">
    <actuator name="arm_motor_4"/>
    <joint name="arm_joint_4"/>
    <mechanicalReduction>1</mechanicalReduction>
  </transmission>
  <transmission name="arm_trans_5" type="pr2_mechanism_model/SimpleTransmission">
    <actuator name="arm_motor_5"/>
    <joint name="arm_joint_5"/>
    <mechanicalReduction>1</mechanicalReduction>
  </transmission>
  <joint name="gripper_palm_joint" type="fixed">
    <origin rpy="0 0 0" xyz="0 0 0"/>
    <parent link="arm_link_5"/>
    <child link="gripper_palm_link"/>
  </joint>
  <link name="gripper_palm_link">
    <inertial>
      <origin rpy="0 0 0" xyz="0 0 0"/>
      <mass value="0.1"/>
      <inertia ixx="0.01" ixy="0" ixz="0" iyy="0.01" iyz="0" izz="0.01"/>
    </inertial>
    <visual>
      <origin rpy="0 0 0" xyz="0 0 0"/>
      <geometry>
        <mesh filename="package://youbot_description/meshes/youbot_gripper/palm.dae"/>
      </geometry>
      <material name="Black"/>
    </visual>
    <collision>
      <origin rpy="0 0 0" xyz="0 0 0"/>
      <geometry>
        <!--<box size="0.050 0.094 0.054"/>-->
        <mesh filename="package://youbot_description/meshes/youbot_gripper/palm_convex.dae"/>
      </geometry>
    </collision>
  </link>
  <joint name="gripper_finger_joint_l" type="prismatic">
    <origin rpy="0 0 3.14159265359" xyz="0.004 0.008 0.046"/>
    <parent link="gripper_palm_link"/>
    <child link="gripper_finger_link_l"/>
    <axis xyz="0 -1 0"/>
    <dynamics damping="1.0" friction="1.0"/>
    <limit effort="1" lower="0" upper="0.0115" velocity="0.1"/>
    <safety_controller k_position="20" k_velocity="25" soft_lower_limit="0.001" soft_upper_limit="0.011"/>
  </joint>
  <link name="gripper_finger_link_l">
    <inertial>
      <origin rpy="0 0 0" xyz="0 -0.001 0"/>
      <mass value="0.01"/>
      <inertia ixx="0.01" ixy="0" ixz="0" iyy="0.01" iyz="0" izz="0.01"/>
    </inertial>
    <visual>
      <origin rpy="0 0 0" xyz="0 0 0"/>
      <geometry>
        <mesh filename="package://youbot_description/meshes/youbot_gripper/finger.dae"/>
      </geometry>
      <material name="Black"/>
    </visual>
    <collision>
      <origin rpy="0 0 0" xyz="0 0 0"/>
      <geometry>
        <!--<box size="0.014 0.020 0.046"/>-->
        <mesh filename="package://youbot_description/meshes/youbot_gripper/finger_convex.dae"/>
      </geometry>
    </collision>
  </link>
  <joint name="gripper_finger_joint_r" type="prismatic">
    <origin rpy="0 0 0" xyz="0.004 -0.008 0.046"/>
    <parent link="gripper_palm_link"/>
    <child link="gripper_finger_link_r"/>
    <axis xyz="0 -1 0"/>
    <dynamics damping="1.0" friction="1.0"/>
    <limit effort="1" lower="0" upper="0.0115" velocity="0.1"/>
    <safety_controller k_position="20" k_velocity="25" soft_lower_limit="0.001" soft_upper_limit="0.011"/>
  </joint>
  <link name="gripper_finger_link_r">
    <inertial>
      <origin rpy="0 0 0" xyz="0.000 -0.001 0"/>
      <mass value="0.01"/>
      <inertia ixx="0.01" ixy="0" ixz="0" iyy="0.01" iyz="0" izz="0.01"/>
    </inertial>
    <visual>
      <origin rpy="0 0 0" xyz="0 0 0"/>
      <geometry>
        <mesh filename="package://youbot_description/meshes/youbot_gripper/finger.dae"/>
      </geometry>
      <material name="Black"/>
    </visual>
    <collision>
      <origin rpy="0 0 0" xyz="0.000 0 0"/>
      <geometry>
        <!--<box size="0.014 0.020 0.046"/>-->
        <mesh filename="package://youbot_description/meshes/youbot_gripper/finger_convex.dae"/>
      </geometry>
    </collision>
  </link>
  <joint name="gripper_tip_joint" type="fixed">
    <origin rpy="0.0 -1.57079632679 0.0" xyz="0.004 0 0.08"/>
    <parent link="gripper_palm_link"/>
    <child link="gripper_tip"/>
  </joint>
  <link name="gripper_tip">
    <inertial>
      <mass value="0.001"/>
      <origin xyz="0 0 0"/>
      <inertia ixx="0.001" ixy="0.0" ixz="0.0" iyy="0.001" iyz="0.0" izz="0.001"/>
    </inertial>
  </link>
  <joint name="usb_cam_joint" type="fixed">
    <origin rpy="1.49224 3.09978 1.5769" xyz="-0.0417 -0.0078 0.0207"/>
    <!--<origin xyz="-0.0928 -0.0117 0.0431" rpy="1.50579 2.83312 1.6295" />-->
    <!--<origin xyz="-0.02476 -0.0244 0.0125" rpy="2.67678 3.15999 3.05878" /> -->
    <parent link="gripper_tip"/>
    <child link="usb_cam"/>
  </joint>
  <link name="usb_cam">
    <inertial>
      <mass value="0.001"/>
      <origin xyz="0 0 0"/>
      <inertia ixx="0.001" ixy="0.0" ixz="0.0" iyy="0.001" iyz="0.0" izz="0.001"/>
    </inertial>
  </link>
  <gazebo reference="gripper_palm_link">
    <material>Gazebo/Black</material>
    <turnGravityOff>false</turnGravityOff>
    <selfCollide>true</selfCollide>
  </gazebo>
  <gazebo reference="gripper_finger_l_link">
    <material>Gazebo/Black</material>
    <turnGravityOff>false</turnGravityOff>
    <selfCollide>true</selfCollide>
  </gazebo>
  <gazebo reference="gripper_finger_r_link">
    <material>Gazebo/Black</material>
    <turnGravityOff>false</turnGravityOff>
    <selfCollide>true</selfCollide>
  </gazebo>
  <transmission name="gripper_finger_l_trans" type="pr2_mechanism_model/SimpleTransmission">
    <actuator name="gripper_finger_l_motor"/>
    <joint name="gripper_finger_joint_l"/>
    <mechanicalReduction>1</mechanicalReduction>
  </transmission>
  <transmission name="gripper_finger_r_trans" type="pr2_mechanism_model/SimpleTransmission">
    <actuator name="gripper_finger_r_motor"/>
    <joint name="gripper_finger_joint_r"/>
    <mechanicalReduction>1</mechanicalReduction>
  </transmission>
  <!-- BRSU SPECIFIC STUFF -->
  <material name="Blue">
    <color rgba="0.0 0.0 0.8 1.0"/>
  </material>
  <material name="LightGrey">
    <color rgba="0.82 0.82 0.82 1.0"/>
  </material>
  <!-- Sensor angle on arm -->
  <link name="arm_sensor_angle_part1_link">
    <inertial>
      <mass value="0.01"/>
      <origin rpy="0 0 0" xyz="0 0 0"/>
      <inertia ixx="0.0001" ixy="0" ixz="0" iyy="0.0001" iyz="0" izz="0.0001"/>
    </inertial>
    <visual>
      <origin rpy="0 0 0" xyz="0 0 0"/>
      <geometry>
        <box size="0.0625 0.097 0.0015"/>
      </geometry>
      <material name="Black"/>
    </visual>
    <collision>
      <origin rpy="0 0 0" xyz="0 0 0"/>
      <geometry>
        <box size="0.0625 0.097 0.0015"/>
      </geometry>
    </collision>
  </link>
  <joint name="arm_sensor_angle_part1_joint" type="fixed">
    <origin rpy="0.0 0.0 0.0" xyz="-0.002 0.0 -0.023"/>
    <parent link="arm_link_5"/>
    <child link="arm_sensor_angle_part1_link"/>
  </joint>
  <link name="arm_sensor_angle_part2_link">
    <inertial>
      <mass value="0.01"/>
      <origin rpy="0 0 0" xyz="0 0 0"/>
      <inertia ixx="0.0001" ixy="0" ixz="0" iyy="0.0001" iyz="0" izz="0.0001"/>
    </inertial>
    <visual>
      <origin rpy="0 0 0" xyz="0 0 0"/>
      <geometry>
        <box size="0.0625 0.097 0.0015"/>
      </geometry>
      <material name="Black"/>
    </visual>
    <collision>
      <origin rpy="0 0 0" xyz="0 0 0"/>
      <geometry>
        <box size="0.0625 0.097 0.0015"/>
      </geometry>
    </collision>
  </link>
  <joint name="arm_sensor_angle_part2_joint" type="fixed">
    <origin rpy="0 1.57079632679 0 " xyz="-0.0305 0 0.0305"/>
    <parent link="arm_sensor_angle_part1_link"/>
    <child link="arm_sensor_angle_part2_link"/>
  </joint>
  <!-- ASUS Xtion on arm sensor angle -->
  <!--
  <xacro:asus_xtion_camera name="openni" parent="arm_sensor_angle_part2_link"  tilt="0.0">
    <origin xyz="0.01 0.0 0.0" rpy="${M_PI} 0.0 ${M_PI}" />
  </xacro:asus_xtion_camera> 
-->
  <!--
  <xacro:kinect_camera name="kinect" parent="arm_link_5">
    <origin xyz="-0.1 0.0 0.0" rpy="${M_PI} 0.0 ${M_PI}" />
	</xacro:kinect_camera>
-->
  <!-- Microsoft LifeCam on gripper -->
  <joint name="microsoft_lifecam_camera_joint" type="fixed">
    <origin rpy="0 3.14159265359 0" xyz="-0.04 0 -0.03"/>
    <parent link="arm_sensor_angle_part2_link"/>
    <child link="microsoft_lifecam_camera"/>
  </joint>
  <link name="microsoft_lifecam_camera">
    <inertial>
      <mass value="0.01"/>
      <origin xyz="0 0 0"/>
      <inertia ixx="0.001" ixy="0.0" ixz="0.0" iyy="0.001" iyz="0.0" izz="0.001"/>
    </inertial>
    <visual>
      <origin rpy="1.57079632679 0 1.57079632679" xyz="-0.04 -0.0035 -0.031"/>
      <geometry>
        <mesh filename="package://youbot_description/meshes/sensors/microsoft_lifecam.dae" scale="0.001 0.001 0.001"/>
      </geometry>
    </visual>
    <collision>
      <origin rpy="1.57079632679 0 1.57079632679" xyz="-0.04 -0.0035 -0.031"/>
      <geometry>
        <mesh filename="package://youbot_description/meshes/sensors/microsoft_lifecam.dae" scale="0.001 0.001 0.001"/>
      </geometry>
    </collision>
  </link>
  <gazebo reference="microsoft_lifecam_camera">
    <sensor name="camera" type="camera">
      <camera>
        <horizontal_fov>1.2217304764</horizontal_fov>
        <image>
          <format>R8G8B8</format>
          <width>800</width>
          <height>480</height>
        </image>
        <clip>
          <near>0.01</near>
          <far>5</far>
        </clip>
      </camera>
      <plugin filename="libgazebo_ros_camera.so" name="gazebo_ros_camera">
        <alwaysOn>true</alwaysOn>
        <updateRate>15.0</updateRate>
        <imageTopicName>/usb_cam/image_raw</imageTopicName>
        <cameraInfoTopicName>/usb_cam/camera_info</cameraInfoTopicName>
        <frameName>/microsoft_lifecam_frame</frameName>
        <distortion_k1>0.00000001</distortion_k1>
        <distortion_k2>0.00000001</distortion_k2>
        <distortion_k3>0.00000001</distortion_k3>
        <distortion_t1>0.00000001</distortion_t1>
        <distortion_t2>0.00000001</distortion_t2>
      </plugin>
    </sensor>
  </gazebo>
</robot>
